Workbook

Sheet Model_example_using2anchor
B1: Today | C1: =TODAY() -> 45830
B2: Daily Settle Prices | C2: =DATEVALUE("10/06/2025") -> 45818 | N2: From: (Avg. SONIA) = (% days before meet.)*(SONIA Start)+(% days after meet)*(SONIA End)
B3: 1 | C3: 2 | D3: 3 | E3: 4 | F3: 1 | G3: 2 | N3: SONIA End = [ (Avg. SONIA) - (% days before meet.)*(SONIA Start) ] / (% days after meet.)
A4: Contract start date: | B4: 45627 | C4: 45717 | D4: 45809 | E4: 45901 | F4: 45992 | N4: SONIA Start = [ (Avg SONIA) - (% days after meet.)*(SONIA End) ] / (% days before meet.)
C5: 95.627 | D5: 95.855 | E5: 96.095 | F5: 45992
C8: Price | D8: Implied Rate | F8: M = # of days after the LAST MPC until the delivery date of the 3-months SONIA contract
B9: Q2 (No MPC's meeting left on 22/5/2025) | C9: =C5 -> 95.627 | D9: =100-C9 -> 4.373 | F9: N = # of days before the LAST MPC that the 3-months SONIA contract cover
B10: Q3 | C10: =D5 -> 95.855 | D10: =100-C10 -> 4.145 | F10: M -> | G10: 0
B11: Q4 | C11: =E5 -> 96.095 | D11: =100-C11 -> 3.905 | F11: N -> | G11: 1
B13: Using Q2 as an Anchor month | J13: Hike/Cut Size Probabilities for the next 2 MPC meeting
C14: Days | D14: % Days | E14: Price | F14: Implied Rate | G14: Quarterly Change | H14: # of 25bp Hikes/Cut | I14: # Hikes/Cut Breakdown | J14: 0bps | K14: 25bps | L14: 50bps | M14: 75bps | N14: 100bps
B16: Q3 (End) | C16: =G10 -> 0 | D16: =C16/(C16+C18) -> 0 | E16: =(E17-(D18*E18))/D16 -> #DIV/0! | F16: =100-E16 -> #DIV/0! | G16: =F16-F18 -> #DIV/0! | H16: =G16/25*100 -> #DIV/0! | I16: =ABS(TRUNC(H16,0)) -> #DIV/0!
B17: Q3 (Avg) | E17: =D5 -> 95.855 | F17: =100-E17 -> 4.145 | I17: =MOD(ABS(H16),1) -> #DIV/0! | J17: =IF(I16=0,1-I17,0) -> #DIV/0! | K17: =IF(I16=0,I17,IF(I16=1,1-I17,0)) -> #DIV/0! | L17: =IF(I16=0,I17-I17,IF(I16=1,I17,IF(I16=2,1-I17,0))) -> #DIV/0! | M17: =IF(K17 + L17 = 1, 0, IF(I16 = 0, 0, IF(I16 = 1, I17, IF(I16 = 2, I17, IF(I16 = 3, 1 - I17, 0))))) -> #DIV/0! | N17: 0
B18: Q3 (Start) | C18: =G11 -> 1 | D18: =C18/(C18+C16) -> 1 | E18: =E19 -> 95.627 | F18: =100-E18 -> 4.373
A19: Start here --> | B19: Q2 | E19: =C9 -> 95.627 | F19: =100-E19 -> 4.373
P22: Future Contract | Q22: Bank of England's (BoE) Monetary Policy Committee (MPC) meeting schedule for 2025
Q23: February: Thursday, February 6
P24: 45717 | Q24: March: Thursday, March 20
P25: 45717 | Q25: May: Thursday, May 8 | R25: =DATEVALUE("08/05/2025") -> 45785
C26: Price | D26: Implied Rate | P26: 45809 | Q26: June: Thursday, June 19 | S26: No cut!
B27: Q4 (Anchor 3-month contract) | C27: =E5 -> 96.095 | D27: =100-C27 -> 3.905 | P27: 45809 | Q27: August: Thursday, August 7 | R27: =DATEVALUE("07/08/2025") -> 45876
P28: 45901 | Q28: September: Thursday, September 18
B29: Using Q4 as an Anchor month | J29: Hike/Cut Size Probabilities for the next 2 MPC meeting | P29: 45901 | Q29: November: Thursday, November 6 | R29: =DATEVALUE("06/11/2025") -> 45967
C30: Days | D30: % Days | E30: Price | F30: Implied Rate | G30: Quarterly Change | H30: # of 25bp Hikes/Cut | I30: # Hikes/Cut Breakdown | J30: 0bps | K30: 25bps | L30: 50bps | M30: 75bps | N30: 100bps | P30: 45992 | Q30: December: Thursday, December 18
P31: Contract start date:
B32: Q4 | E32: =C27 -> 96.095 | F32: =100-E32 -> 3.905 | P32: 45717 | Q32: March: March 19, 2025
B33: Q3 (End) | C33: =G10 -> 0 | D33: =C33/(C33+C35) -> 0 | E33: =E32 -> 96.095 | F33: =100-E33 -> 3.905 | G33: =F33-F35 -> -0.24 | H33: =G33/25*100 -> -0.96 | I33: =ABS(TRUNC(H33,0)) -> 0 | P33: 45809 | Q33: June: June 18, 2025 | R33: =DATEVALUE("18/06/2025") -> 45826
B34: Q3 (Avg) | E34: =D5 -> 95.855 | F34: =100-E34 -> 4.145 | I34: =MOD(ABS(H33),1) -> 0.96 | J34: =IF(I33=0,1-I34,0) -> 0.04 | K34: =IF(I33=0,I34,IF(I33=1,1-I34,0)) -> 0.96 | L34: =IF(I33=0,I34-I34,IF(I33=1,I34,IF(I33=2,1-I34,0))) -> 0 | M34: =IF(K34 + L34 = 1, 0, IF(I33 = 0, I34, IF(I33 = 1, I34, IF(I33 = 2, I34, IF(I33 = 3, 1 - I34, 0))))) -> 0.96 | N34: 0 | P34: 45901 | Q34: September: September 17, 2025 | R34: =DATEVALUE("17/09/2025") -> 45917
B35: Q3 (Start) | C35: =G11 -> 1 | D35: =C35/(C35+C33) -> 1 | E35: =((E34)-(D33*E33))/D35 -> 95.855 | F35: =100-E35 -> 4.145 | P35: 45992 | Q35: December: December 17, 2025 | R35: =DATEVALUE("17/12/2025") -> 46008
B37: Methodology:
B38: 1. Get daily FF settlement prices by contract.
B39: 2. Find the nearest upcoming month without an MPC meeting.
B40: 3. Avg. Month Price = Daily Settle Price
B41: 4. Because SONIA(end)T-1 = SONIA(beg)T, fill out those cells.
B42: 5. Calculate the adjacent SONIA Start/End using the formulas above.
B43: 6. Calculate the Quartly Change for the quarter with MPC meetings (Col. G). | O43: Cut Size
B44: 7. Calculate the # of 25bp hikes based off of Quarterly Change (Col. H): | O44: 25 bp | P44: =K17 -> #DIV/0! | Q44: =K34 -> 0.96
B45: 7.1. =((Monthly Change)/25)*100 | O45: 50 bp | P45: =L34 -> 0 | Q45: =L17 -> #DIV/0!
B46: 7.2. Break down the number of 25bp hikes into full hikes and remainder [Use Trunc() and Mod()]. | O46: 75 bp | P46: =M34 -> 0.96 | Q46: =M17 -> #DIV/0!
B47: 8. We can start calculating the probability tree - start with the nearest MPC meeting:
...

Sheet Note_using the next Q as anchor
A1: As there will be BoE MoC's meeting in the following quarter, we need to take into account of the over or underestimation of the probability of rate cut/hike as a result of the presence of the MoC meeting.
A2: This means, if (the last of) the MoC within the contract period announces a rate hike, the implied SONIA(End)T<SONIA(Avg)T-1.
A3: We can take this into consideration and caveat, or assuming that SONIA(End)T = SONIA(Avg)T-1, where T is the Quarter the Future Contract covers over which we are interested in the MOC's probability of rate hike/cut.# (i.e. T-1 is the anchor period)

Sheet CFA_Methodology_not useful
B1: Today | C1: =TODAY() -> 45830 | G1: NB: In the UK it doesn't appear to have an equivalence of forward guidance target rate range. So the closest we have would be the SONIA rate itself
B2: Daily Settle Prices | C2: =C1 -> 45830
B3: 1 | C3: 2 | D3: 3 | E3: 4 | G3: CFA formula on the implied probability of rate hike/cut: Implied EFFR - Current Federal fund rate target/(0.25), given each rate hike/cut is by 25bps
A4: Contract start date: | B4: 45627 | C4: 45717 | D4: 45809 | E4: 45901
C5: =Model_example_using2anchor!C5 -> 95.627 | D5: =Model_example_using2anchor!D5 -> 95.855 | E5: =Model_example_using2anchor!E5 -> 96.095 | G5: The problem with the BoE is that, unlike FED, it does not provide a forward guidance on their target range of where interest rate will be.
G6: If we are willing to assume the current SONIA rate to be proxy of the target range (which we shouldn't), then we can obtain the implied probability of rate hike/cut. However, that will be more of an expected target range by the market of where rate might be at the end of the current contract.
C8: Price | D8: Implied Rate | E8: Current SONIA rate
B9: Q2 (No MPC's meeting left on 22/5/2025) | C9: =Model_example_using2anchor!C5 -> 95.627 | D9: =100-C9 -> 4.373 | E9: 4.212
B10: Q3 | C10: =Model_example_using2anchor!D5 -> 95.855 | D10: =100-C10 -> 4.145
B11: Q4 | C11: =Model_example_using2anchor!E5 -> 96.095 | D11: =100-C11 -> 3.905
B12: Q1 | C12: 96.225 | D12: =100-C12 -> 3.775
B16: Probability of a rate hike/cut
C17: 0bps | D17: 25bps | E17: 50bps | F17: 75bps
B18: Q3 | C18: =IF((D10 - E9)/0.25 < 0, 1-(ABS(D18)),0) -> 0.732 | D18: =IF((D10 - E9)/0.25 > 0, E18 - 1, (D10 - E9)/0.25) -> -0.268 | E18: =IF((D10 - E9)/0.25 > 0, MOD((D10 - E9)/0.25, 1), 0) -> 0
B19: Q4 | C19: =IF((D11 - E9)/0.25 < 0, 1-(ABS(D19)),0) -> -0.228 | D19: =IF((D11 - E9)/0.25 > 0, E19 - 1, (D11 - E9)/0.25) -> -1.228 | E19: =IF((D11 - E9)/0.25 > 0, MOD((D11 - E9)/0.25, 1), 0) -> 0
B22: This implies 13% of 1 rate cut only in the next 2 MPC meetings and 81% of 1 rate cut in the next 4 meetings.
E25: =IF((D10 - E9)/0.25 > 0, E18 - 1, (D10 - E9)/0.25) -> -0.268
